<a name="JJM0q"></a>
## 一、异步 & 事件循环  <!-- {docsify-ignore-all} -->
以promise， async/await， setTimeout等异步任务为主的代码执行顺序题，主要考察对`JS执行机制`及`先同后异，先微后宏`的理解

> [!Tip]
> **一些注意点：**  
> - new Promise，会同步执行其构造器，所以new Promise里的同步代码会被立即执行;  
> - promise内部的状态发生变化，才会执行then或catch;  
> - 如果async函数中抛出了错误，就会终止错误结果，不会继续向下执行;  
> - 在 JavaScript 中，如果一个 .then() 或 .catch() 方法没有返回值，则默认返回 undefined;


### promise相关总结
在 JavaScript 中，区分“立即解决的 Promise”和其他情况主要依据是 Promise 是否在其执行器函数（executor function）中直接调用了 resolve() 或 reject()。下面我会说明“立即解决的 Promise”与“非立即解决的 Promise”之间的区别。

**立即解决的 Promise**：

- Promise 的状态转变（从 pending 到 fulfilled 或 rejected）在 Promise 执行器函数的执行过程中立即发生。
- 解决或拒绝的值将异步通过微任务队列传递。

**非立即解决的 Promise**：

- Promise 的状态转变取决于某个异步操作的完成。
- resolve 或 reject 在未来某个时间点调用，通常依赖于如 setTimeout、setInterval、网络请求回调等异步操作。

理解这些差异有助于更好地设计和理解涉及异步操作的 JavaScript 程序，特别是在处理复杂的异步流程和并发操作时。
<a name="PRfzM"></a>
#### 立即解决的 Promise
如之前例子中所示，这种 Promise 在创建时立即调用了 resolve 或 reject：
```javascript
let immediatePromise = new Promise((resolve, reject) => {
  console.log("Promise is being resolved immediately.");
  resolve("Resolved immediately");
});
```
在这个例子中，resolve("Resolved immediately") 是在 Promise 的执行器函数中直接调用的。尽管解决操作是异步处理的（即解决值会在微任务队列中异步传递），但从技术上讲，Promise 的状态转变（从 pending 到 fulfilled）是立即发生的。
<a name="bd9TP"></a>
#### 非立即解决的 Promise
“非立即解决的 Promise”通常指的是 Promise 的解决依赖于某些异步操作的完成，例如 I/O 操作、延时等。这意味着 resolve 或 reject 调用发生在未来的某个时间点，而非在 Promise 创建的过程中立即发生：
```javascript
let delayedPromise = new Promise((resolve, reject) => {
  setTimeout(() => {
    console.log("Promise is being resolved after a delay.");
    resolve("Resolved after 2 seconds");
  }, 2000);
});
```
在这个例子中，resolve 是在 setTimeout 的回调函数中调用的，而 setTimeout 本身设置了一个至少延迟 2 秒的定时器。因此，Promise 的状态改变发生在未来，不是在 Promise 创建的过程中立即发生。


<a name="fsj4A"></a>
### 1. 练习题
```javascript
const promise = new Promise((resolve, reject) => {
  console.log(1);
  console.log(2);
});
promise.then(() => {
  console.log(3);
});
console.log(4);
```
输出结果如下：
```javascript
1 
2 
4
```
promise.then 是微任务，它会在所有的宏任务执行完之后才会执行，同时需要promise内部的状态发生变化，才会执行then或catch。因为这里内部没有发生变化，一直处于pending状态，所以不输出3。
<a name="RjJjC"></a>
### 2. 练习题
```javascript
const promise1 = new Promise((resolve, reject) => {
  console.log('promise1')
  resolve('resolve1')
})
const promise2 = promise1.then(res => {
  console.log(res)
})
console.log('1', promise1);
console.log('2', promise2);
```
输出结果如下：
```javascript
promise1
1 Promise{<resolved>: resolve1}
2 Promise{<pending>}
resolve1
```
**需要注意的是，直接打印promise函数，会打印出它的状态值和参数。**

<a name="h5fag"></a>
### 3. 练习题
```javascript
const promise = new Promise((resolve, reject) => {
  console.log(1);
  setTimeout(() => {
    console.log("timerStart");
    resolve("success");
    console.log("timerEnd");
  }, 0);
  console.log(2);
});
promise.then((res) => {
  console.log(res);
});
console.log(4);
```
输出结果如下：
```javascript
1
2
4
timerStart
timerEnd
success
```
<a name="CJhTg"></a>
### 4. 练习题
```javascript
Promise.resolve().then(() => {
  console.log('promise1');
  const timer2 = setTimeout(() => {
    console.log('timer2')
  }, 0)
});
const timer1 = setTimeout(() => {
  console.log('timer1')
  Promise.resolve().then(() => {
    console.log('promise2')
  })
}, 0)
console.log('start');
```
输出结果如下：
```javascript
start
promise1
timer1
promise2
timer2
```
<a name="bdDcr"></a>
### 5. 练习题
```javascript
const promise = new Promise((resolve, reject) => {
    resolve('success1');
    reject('error');
    resolve('success2');
});
promise.then((res) => {
    console.log('then:', res);
}).catch((err) => {
    console.log('catch:', err);
})
```
输出结果如下：
```javascript
then：success1
```
这个题目考察的就是**Promise的状态在发生变化之后，就不会再发生变化**。开始状态由`pending`变为`resolve`，说明已经变为已完成状态，下面的两个状态的就不会再执行，同时下面的catch也不会捕获到错误。
<a name="1Xu9k"></a>
### 6. 练习题
```javascript
Promise.resolve(1)
  .then(2)
  .then(Promise.resolve(3))
  .then(console.log)
```
输出结果如下：
```javascript
1
```
 看到这个题目，好多的then，实际上只需要记住一个原则：`.then` 或`.catch` 的参数期望是函数，传入非函数则会发生**值透传**。
第一个then和第二个then中传入的都不是函数，一个是数字，一个是对象，因此发生了透传，将`resolve(1)` 的值直接传到最后一个then里，直接打印出1
<a name="gdokr"></a>
### 7. 练习题
```javascript
const promise1 = new Promise((resolve, reject) => {
  setTimeout(() => {
    resolve('success')
  }, 1000)
})
const promise2 = promise1.then(() => {
  throw new Error('error!!!')
})
console.log('promise1', promise1)
console.log('promise2', promise2)
setTimeout(() => {
  console.log('promise1', promise1)
  console.log('promise2', promise2)
}, 2000)
```
输出结果如下：
```javascript
promise1 Promise {<pending>}
promise2 Promise {<pending>}

Uncaught (in promise) Error: error!!!
promise1 Promise {<fulfilled>: "success"}
promise2 Promise {<rejected>: Error: error!!}
```
<a name="SaxlH"></a>
### 8. 练习题
```javascript
Promise.resolve(1)
  .then(res => {
    console.log(res);
    return 2;
  })
  .catch(err => {
    return 3;
  })
  .then(res => {
    console.log(res);
  });
```
输出结果如下：
```javascript
1   
2
```
上面的输出结果之所以依次打印出1和2，是因为`resolve(1)`之后走的是第一个then方法，并没有进catch里，所以第二个then中的res得到的实际上是第一个then的返回值。并且return 2会被包装成`resolve(2)`，被最后的then打印输出2。
<a name="yPVep"></a>
### 9. 练习题
```javascript
Promise.resolve().then(() => {
  return new Error('error!!!')
}).then(res => {
  console.log("then: ", res)
}).catch(err => {
  console.log("catch: ", err)
})
```
输出结果如下：
```javascript
"then: " "Error: error!!!"
```
返回任意一个非 promise 的值都会被包裹成 promise 对象，因此这里的`return new Error('error!!!')`也被包裹成了`return Promise.resolve(new Error('error!!!'))`，因此它会被then捕获而不是catch。
<a name="GbsZi"></a>
### 10. 练习题
```javascript
const promise = Promise.resolve().then(() => {
  return promise;
})
promise.catch(console.err)
```
输出结果如下：
```javascript
Uncaught (in promise) TypeError: Chaining cycle detected for promise #<Promise>
```
这里其实是一个坑，`.then` 或 `.catch` 返回的值不能是 promise 本身，否则会造成死循环。

<a name="DU23I"></a>
### 11. 练习题
```javascript
Promise.reject('err!!!')
  .then((res) => {
    console.log('success', res)
  }, (err) => {
    console.log('error', err)
  }).catch(err => {
    console.log('catch', err)
  })
```
输出结果如下：
```javascript
error err!!!
```
我们知道，`.then`函数中的两个参数：

- 第一个参数是用来处理Promise成功的函数
- 第二个则是处理失败的函数

也就是说`Promise.resolve('1')`的值会进入成功的函数，`Promise.reject('2')`的值会进入失败的函数。

在这道题中，错误直接被`then`的第二个参数捕获了，所以就不会被`catch`捕获了，输出结果为：`error err!!!'`

但是，如果是像下面这样：
```javascript
Promise.resolve()
  .then(function success (res) {
    throw new Error('error!!!')
  }, function fail1 (err) {
    console.log('fail1', err)
  }).catch(function fail2 (err) {
    console.log('fail2', err)
  })
```
在`then`的第一参数中抛出了错误，那么他就不会被第二个参数不活了，而是被后面的`catch`捕获到。
<a name="h7mqR"></a>
### 12. 练习题
```javascript
Promise.resolve('1')
  .then(res => {
    console.log(res)
  })
  .finally(() => {
    console.log('finally')
  })
Promise.resolve('2')
  .finally(() => {
    console.log('finally2')
  	return '我是finally2返回的值'
  })
  .then(res => {
    console.log('finally2后面的then函数', res)
  })
```
输出结果如下：
```javascript
1
finally2
finally
finally2后面的then函数 2
```
为什么 finally2 先于 finally 被输出？

- **顺序执行**：Promise.resolve('2') 的 finally 回调在 Promise.resolve('1') 的 finally 回调之前被放入微任务队列，因此它会先执行。
- **原理**：
   - Promise.resolve('1') 的 then 回调先被添加到微任务队列。
   - 紧接着 Promise.resolve('2') 的 finally 回调被添加到微任务队列。
   - 再次 Promise.resolve('2') 的 then 回调被添加到微任务队列。
   - 最后 Promise.resolve('1') 的 finally 回调被添加到微任务队列。

<a name="Dz7jC"></a>
### 13. 练习题
`.finally()`的错误捕获：
```javascript
Promise.resolve('1')
  .finally(() => {
    console.log('finally1')
    throw new Error('我是finally中抛出的异常')
  })
  .then(res => {
    console.log('finally后面的then函数', res)
  })
  .catch(err => {
    console.log('捕获错误', err)
  })
```
输出结果为：
```javascript
'finally1'
'捕获错误' Error: 我是finally中抛出的异常
```
<a name="EJi1Q"></a>
### 14. 练习题
注：resolve()只能接收一个参数
```javascript
function runAsync (x) {
    const p = new Promise(r => 
      // r = resolve
      setTimeout(() => 
        r(x, console.log(x)), 1000))
  
    return p
}

Promise.all([runAsync(1), runAsync(2), runAsync(3)]).then(res => console.log(res))
```
输出结果如下：
```javascript
1
2
3
[1, 2, 3]
```
首先，定义了一个Promise，来异步执行函数runAsync，该函数传入一个值x，然后间隔一秒后打印出这个x。
之后再使用`Promise.all`来执行这个函数，执行的时候，看到一秒之后输出了1，2，3，同时输出了数组[1, 2, 3]，三个函数是同步执行的，并且在一个回调函数中返回了所有的结果。并且结果和函数的执行顺序是一致的。
<a name="PlEUa"></a>
### 15. 练习题
```javascript
function runAsync (x) {
  const p = new Promise(r => setTimeout(() => r(x, console.log(x)), 1000))
  return p
}
function runReject (x) {
  const p = new Promise((res, rej) => setTimeout(() => rej(`Error: ${x}`, console.log(x)), 1000 * x))
  return p
}
Promise.all([runAsync(1), runReject(4), runAsync(3), runReject(2)])
       .then(res => console.log(res))
       .catch(err => console.log(err))
```
输出结果如下：
```javascript
// 1s后输出
1
3
// 2s后输出
2
Error: 2
// 4s后输出
4
```
 根据 Promise.all 的行为，若任何一个 Promise 被拒绝，整个 Promise.all 会立即拒绝。  
**时间线及输出顺序**

1. **1 秒后**:
   - runAsync(1) 解决并打印 1。
   - runAsync(3) 解决并打印 3。
2. **2 秒后**:
   - runReject(2) 被拒绝并打印 2，导致 Promise.all 立即拒绝，并执行 catch 回调。
3. **4 秒后**:
   - runReject(4) 被拒绝并打印 4。

**关键点**

- Promise.all 的 catch 回调在第一个 Promise 被拒绝时触发，但这不会影响其他 Promise 的继续执行。
- 所有传递给 Promise.all 的 Promise 都会继续运行到它们各自的完成状态（解决或拒绝），即使 Promise.all 本身已经拒绝并执行了 catch 回调。 因此即使在 Promise.all 已经拒绝的情况下，其他 Promise 仍然会继续执行并打印结果。  
<a name="luBcL"></a>
### 16. 练习题
```javascript
function runAsync (x) {
  const p = new Promise(r => setTimeout(() => r(x, console.log(x)), 1000))
  return p
}
Promise.race([runAsync(1), runAsync(2), runAsync(3)])
  .then(res => console.log('result: ', res))
  .catch(err => console.log(err))
```
输出结果如下：
```javascript
1
'result: ' 1
2
3
```
**为什么 result: 1 在 2 和 3 之前被打印？**

1. 在 setTimeout 回调（宏任务）中，runAsync(1) 首先解决并打印 1。
2. 由于 Promise.race 立刻检测到第一个解决的 Promise 并触发其 then 回调，该 then 回调会被放入微任务队列。
3. JavaScript 事件循环会在所有宏任务完成后执行微任务，因此 then 回调在打印 2 和 3 之前执行，打印 result: 1。
<a name="QOpSF"></a>
### 17. 练习题
```javascript
function runAsync(x) {
  const p = new Promise(r =>
    setTimeout(() => r(x, console.log(x)), 1000)
  );
  return p;
}
function runReject(x) {
  const p = new Promise((res, rej) =>
    setTimeout(() => rej(`Error: ${x}`, console.log(x)), 1000 * x)
  );
  return p;
}
Promise.race([runReject(0), runAsync(1), runAsync(2), runAsync(3)])
  .then(res => console.log("result: ", res))
  .catch(err => console.log(err));
```
输出结果如下：
```javascript
0
Error: 0
1
2
3
```
可以看到在catch捕获到第一个错误之后，后面的代码还执行，不过不会再被捕获了。

注意：`all`和`race`传入的数组中如果有会抛出异常的异步任务，那么只有最先抛出的错误会被捕获，并且是被then的第二个参数或者后面的catch捕获；但并不会影响数组中其它的异步任务的执行。
<a name="nURH0"></a>
### 18. 练习题
```javascript
async function async1() {
  console.log("async1 start");
  await async2();
  console.log("async1 end");
}
async function async2() {
  console.log("async2");
}
async1();
console.log('start')
```
输出结果如下：
```javascript
async1 start
async2
start
async1 end
```
代码的执行过程如下：

1. 首先执行函数中的同步代码`async1 start`，之后遇到了`await`，它会阻塞`async1`后面代码的执行，因此会先去执行`async2`中的同步代码`async2`，然后跳出`async1`；
2. 跳出`async1`函数后，执行同步代码`start`；
3. 在一轮宏任务全部执行完之后，再来执行`await`后面的内容`async1 end`。

这里可以理解为await后面的语句相当于放到了new Promise中，下一行及之后的语句相当于放在Promise.then中。
<a name="HCJxD"></a>
### 19. 练习题
```javascript
async function async1() {
  console.log("async1 start");
  await async2();
  console.log("async1 end");
  setTimeout(() => {
    console.log('timer1')
  }, 0)
}
async function async2() {
  setTimeout(() => {
    console.log('timer2')
  }, 0)
  console.log("async2");
}
async1();
setTimeout(() => {
  console.log('timer3')
}, 0)
console.log("start")
```
输出结果如下：
```javascript
async1 start
async2
start
async1 end
timer2
timer3
timer1
```
<a name="GV0yJ"></a>
#### 执行顺序解释：  <!-- {docsify-ignore} -->
**同步任务**  

- 当 async1() 被调用时：
   - console.log("async1 start") 直接执行。
- 进入 async2()：
   - console.log("async2") 直接执行。
- console.log("start") 在全局代码中直接执行。

<a name="fNkV0"></a>  
**宏任务**

- 三个 setTimeout() 调用：
   - setTimeout() 在 async2() 里设置，将来打印 "timer2"。
   - setTimeout() 在 async1() 的 await 之后设置，将来打印 "timer1"。
   - setTimeout() 在全局代码设置，将来打印 "timer3"。
<a name="OJHkO"></a>
**微任务**

- await async2() 造成的微任务：
   - 尽管 async2() 没有显式返回 Promise，await 语句会把函数调用转换为微任务。await 的行为使得 async1() 在它之后的代码转变为微任务，打印 "async1 end"。
<a name="on30e"></a>
#### 执行顺序详解 <!-- {docsify-ignore} -->


1. **同步执行**：
   - 打印 "async1 start"
   - 打印 "async2"
   - 打印 "start"
2. **微任务**：
   - 在当前调用栈清空后执行，打印 "async1 end"。
3. **宏任务队列**（按照它们设置的顺序）：
   - 打印 "timer2"（async2() 中设置）
   - 打印 "timer3"（全局代码中设置）
   - 打印 "timer1"（在 async1() 的 await 之后设置）
<a name="sFWlJ"></a>
#### 结果预测 <!-- {docsify-ignore} -->

这个分析表明，执行顺序和输出如下：
```
plaintext
复制代码
async1 start
async2
start
async1 end
timer2
timer3
timer1
```
这样的分类和分析可以帮助更好地理解代码中的同步操作、异步操作以及事件循环中的微任务和宏任务的执行顺序。

<a name="KLVmX"></a>
### 20. 练习题
```javascript
async function async1 () {
  console.log('async1 start');
  await new Promise(resolve => {
    console.log('promise1')
  })
  console.log('async1 success');
  return 'async1 end'
}
console.log('srcipt start')
async1().then(res => console.log(res))
console.log('srcipt end')
```
输出结果如下：
```javascript
script start
async1 start
promise1
script end
```
**当 async1 被调用时，这里的执行顺序如下：  **

- **同步打印**："async1 start"
- **创建 Promise，同步执行构造器**：
   - 构造器内的代码 console.log('promise1') 被立即执行。这是因为 Promise 构造器内的代码总是同步执行的。这段代码的执行并不取决于 Promise 是异步解决还是根本不解决。
- **await 操作**：
   - 这里的 await 等待一个从未解决的 Promise（因为 resolve 从未被调用），所以它实际上将暂停后续代码的执行。await 之后的代码转换为微任务，将在 Promise 解决后执行，但在这种情况下，这永远不会发生。
<a name="6su6p"></a>
### 21. 练习题
```javascript
async function async1 () {
  console.log('async1 start');
  await new Promise(resolve => {
    console.log('promise1')
    resolve('promise1 resolve')
  }).then(res => console.log(res))
  console.log('async1 success');
  return 'async1 end'
}
console.log('srcipt start')
async1().then(res => console.log(res))
console.log('srcipt end')
```
这里是对上面一题进行了改造，加上了resolve。

输出结果如下：
```javascript
script start
async1 start
promise1
script end
promise1 resolve
async1 success
async1 end
```
**执行顺序详解**

1. **同步执行**：
   - "script start" 打印。
   - "async1 start" 打印。
   - "promise1" 打印。
2. **await 操作**：
   - await 遇到一个立即解决的 Promise。因为这是一个 async 函数，await 后的代码会转变为微任务，等待当前调用栈清空和所有微任务执行完毕。
3. **继续同步代码执行**：
   - "script end" 打印。
4. **微任务处理**：
   - 解决的 Promise 触发 .then()，打印 "promise1 resolve"。
   - 继续执行 async1() 中 await 后的代码，打印 "async1 success"。
5. **处理 async1() 返回的 Promise 的 .then()**：
   - 打印 "async1 end"，这是在 async1() 完全完成后添加到微任务队列的。
<a name="Uzann"></a>
### 22. 练习题
```javascript
async function async1() {
  console.log("async1 start");
  await async2();
  console.log("async1 end");
}

async function async2() {
  console.log("async2");
}

console.log("script start");

setTimeout(function() {
  console.log("setTimeout");
}, 0);

async1();

new Promise(resolve => {
  console.log("promise1");
  resolve();
}).then(function() {
  console.log("promise2");
});
console.log('script end')
```
输出结果如下：
```javascript
script start
async1 start
async2
promise1
script end
async1 end
promise2
setTimeout
```

<a name="TAvek"></a>
### 23. 练习题
```javascript
async function async1 () {
  await async2();
  console.log('async1');
  return 'async1 success'
}
async function async2 () {
  return new Promise((resolve, reject) => {
    console.log('async2')
    reject('error')
  })
}
async1().then(res => console.log(res))
```
输出结果如下：

- 执行这段代码时，首先输出 "async2"，因为这是在 async2 的 Promise 执行器中直接执行的。
- 然后，由于 reject('error') 被调用，async1 中的 await async2() 捕获到拒绝，但没有相应的错误处理代码（如 try...catch 或 .catch()），所以不会打印 "async1"，且不会执行 .then()。
- 最终，程序会显示一个未捕获的异常错误。
```javascript
async2
Uncaught (in promise) error
```
可以看到，如果async函数中抛出了错误，就会终止错误结果，不会继续向下执行。

如果想要让错误不足之处后面的代码执行，可以使用catch来捕获：
```javascript
async function async1 () {
  await Promise.reject('error!!!').catch(e => console.log(e))
  console.log('async1');
  return Promise.resolve('async1 success')
}
async1().then(res => console.log(res))
console.log('script start')
```
这样的输出结果就是：
```javascript
script start
error!!!
async1
async1 success
```
<a name="OShCq"></a>
### 24. 练习题
```javascript
const first = () => (new Promise((resolve, reject) => {
    console.log(3);
    let p = new Promise((resolve, reject) => {
        console.log(7);
        setTimeout(() => {
            console.log(5);
            resolve(6);
            console.log(p)
        }, 0)
        resolve(1);
    });
    resolve(2);
    p.then((arg) => {
        console.log(arg);
    });
}));
first().then((arg) => {
    console.log(arg);
});
console.log(4);
```
输出结果如下：
```javascript
3
7
4
1
2
5
Promise{<resolved>: 1}
```
代码的执行过程如下：

- `p.then(arg => console.log(arg))`先作为内部promise被注册，这将是一个微任务。
- `first().then(arg => console.log(arg))` 在first()内逻辑执行完后被注册，这也是一个微任务。

由于执行已经变为resolved状态，所以`resolve(6)`不会再执行；最后`console.log(p)`打印出`Promise{<resolved>: 1}`；
<a name="fW9kD"></a>
### 25. 练习题
```javascript
const async1 = async () => {
  console.log('async1');
  setTimeout(() => {
    console.log('timer1')
  }, 2000)
  await new Promise(resolve => {
    console.log('promise1')
  })
  console.log('async1 end')
  return 'async1 success'
} 
console.log('script start');
async1().then(res => console.log(res));
console.log('script end');
Promise.resolve(1)
  .then(2)
  .then(Promise.resolve(3))
  .catch(4)
  .then(res => console.log(res))
setTimeout(() => {
  console.log('timer2')
}, 1000)
```
输出结果如下：
```javascript
script start
async1
promise1
script end
1
timer2
timer1
```

<a name="GRxqn"></a>
### 26. 练习题
```javascript
const p1 = new Promise((resolve) => {
  setTimeout(() => {
    resolve('resolve3');
    console.log('timer1')
  }, 0)
  resolve('resovle1');
  resolve('resolve2');
}).then(res => {
  console.log(res)  // resolve1
  setTimeout(() => {
    console.log(p1)
  }, 1000)
}).finally(res => {
  console.log('finally', res)
})
```
执行结果为如下：
```javascript
resolve1
finally  undefined
timer1
Promise {<fulfilled>: undefined}
```
**当 setTimeout() 中打印 p1 时，它显示为 Promise { <fulfilled>: undefined }。这是因为**：

- p1 最初解决为 'resovle1'。
- .then() 处理了这个结果但没有返回新的值。
   - 当 .then() 被调用时，它接收到的值是 'resovle1'，并打印这个值。
   - 但是，在 .then() 方法中没有返回任何东西。在 JavaScript 中，如果一个 .then() 或 .catch() 方法没有返回值，则默认返回 undefined。因此，p1 链的下一个状态被解析为 undefined。
- 因此，整个 Promise 链的结果变为 undefined，导致最终的 Promise 状态显示为 "fulfilled" 但带有 undefined 的结果。
<a name="BgHA8"></a>
### 27. 练习题
```javascript
console.log('1');

setTimeout(function() {
    console.log('2');
    process.nextTick(function() {
        console.log('3');
    })
    new Promise(function(resolve) {
        console.log('4');
        resolve();
    }).then(function() {
        console.log('5')
    })
})
process.nextTick(function() {
    console.log('6');
})
new Promise(function(resolve) {
    console.log('7');
    resolve();
}).then(function() {
    console.log('8')
})

setTimeout(function() {
    console.log('9');
    process.nextTick(function() {
        console.log('10');
    })
    new Promise(function(resolve) {
        console.log('11');
        resolve();
    }).then(function() {
        console.log('12')
    })
})
```
输出结果如下：
```javascript
1
7
6
8
2
4
3
5
9
11
10
12
```
**代码执行顺序分析**
1. **同步代码执行**:
   - console.log('1'); 直接执行。
2. **注册宏任务和微任务**:
   - 第一个 setTimeout 排入宏任务队列，准备执行内部的 console.log('2') 和其他操作。
   - process.nextTick 排入微任务队列，准备执行 console.log('6')。
   - 第一个 Promise 立即解决，并将 .then 回调排入微任务队列，准备执行 console.log('8')。
   - 第二个 setTimeout 排入宏任务队列，准备执行内部的 console.log('9') 和其他操作。
3. **继续同步代码执行**:
   - console.log('7'); 直接执行。
<a name="newmU"></a>
### 事件循环处理微任务和宏任务 <!-- {docsify-ignore} -->


- **处理微任务**:
   - process.nextTick 使得 console.log('6'); 执行。
   - 第一个 Promise.then 使得 console.log('8'); 执行。
- **处理第一个宏任务 (setTimeout)**:
   - console.log('2'); 执行。
   - 内部的 process.nextTick 排入微任务队列，准备执行 console.log('3');。
   - 内部的 Promise 解决并排入微任务队列，.then 回调准备执行 console.log('5');。
   - 处理内部微任务：
      - console.log('3'); 执行。
      - console.log('5'); 执行。
- **处理第二个宏任务 (setTimeout)**:
   - console.log('9'); 执行。
   - 内部的 process.nextTick 排入微任务队列，准备执行 console.log('10');。
   - 内部的 Promise 解决并排入微任务队列，.then 回调准备执行 console.log('12');。
   - 处理内部微任务：
      - console.log('10'); 执行。
      - console.log('12'); 执行。

**（1）第一轮事件循环流程分析如下：**

- 整体script作为第一个宏任务进入主线程，遇到`console.log`，输出1。
- 遇到`setTimeout`，其回调函数被分发到宏任务Event Queue中。暂且记为`setTimeout1`。
- 遇到`process.nextTick()`，其回调函数被分发到微任务Event Queue中。记为`process1`。
- 遇到`Promise`，`new Promise`直接执行，输出7。`then`被分发到微任务Event Queue中。记为`then1`。
- 又遇到了`setTimeout`，其回调函数被分发到宏任务Event Queue中，记为`setTimeout2`。
| 宏任务Event Queue | 微任务Event Queue |
| --- | --- |
| setTimeout1 | process1 |
| setTimeout2 | then1 |

上表是第一轮事件循环宏任务结束时各Event Queue的情况，此时已经输出了1和7。发现了`process1`和`then1`两个微任务：

- 执行`process1`，输出6。
- 执行`then1`，输出8。

第一轮事件循环正式结束，这一轮的结果是输出1，7，6，8。

**（2）第二轮时间循环从**`**setTimeout1**`**宏任务开始：**

- 首先输出2。接下来遇到了`process.nextTick()`，同样将其分发到微任务Event Queue中，记为`process2`。
- `new Promise`立即执行输出4，`then`也分发到微任务Event Queue中，记为`then2`。
| 宏任务Event Queue | 微任务Event Queue |
| --- | --- |
| setTimeout2 | process2 |
|   | then2 |

第二轮事件循环宏任务结束，发现有`process2`和`then2`两个微任务可以执行：

- 输出3。
- 输出5。

第二轮事件循环结束，第二轮输出2，4，3，5。

**（3）第三轮事件循环开始，此时只剩setTimeout2了，执行。**

- 直接输出9。
- 将`process.nextTick()`分发到微任务Event Queue中。记为`process3`。
- 直接执行`new Promise`，输出11。
- 将`then`分发到微任务Event Queue中，记为`then3`。
| 宏任务Event Queue | 微任务Event Queue |
| --- | --- |
|   | process3 |
|   | then3 |

第三轮事件循环宏任务执行结束，执行两个微任务`process3`和`then3`：

- 输出10。
- 输出12。

第三轮事件循环结束，第三轮输出9，11，10，12。

整段代码，共进行了三次事件循环，完整的输出为1，7，6，8，2，4，3，5，9，11，10，12。
<a name="UcJmF"></a>
### 28. 练习题
```javascript
console.log(1)

setTimeout(() => {
  console.log(2)
})

new Promise(resolve =>  {
  console.log(3)
  resolve(4)
}).then(d => console.log(d))

setTimeout(() => {
  console.log(5)
  new Promise(resolve =>  {
    resolve(6)
  }).then(d => console.log(d))
})

setTimeout(() => {
  console.log(7)
})

console.log(8)
```
输出结果如下：
```javascript
1
3
8
4
2
5
6
7
```

<a name="lIVhW"></a>
### 29. 练习题
```javascript
console.log(1);
    
setTimeout(() => {
  console.log(2);
  Promise.resolve().then(() => {
    console.log(3)
  });
});

new Promise((resolve, reject) => {
  console.log(4)
  resolve(5)
}).then((data) => {
  console.log(data);
})

setTimeout(() => {
  console.log(6);
})

console.log(7);
```
练习题如下：
```javascript
1
4
7
5
2
3
6
```

<a name="GMXg4"></a>
### 30. 练习题
```javascript
Promise.resolve().then(() => {
    console.log('1');
    throw 'Error';
}).then(() => {
    console.log('2');
}).catch(() => {
    console.log('3');
    throw 'Error';
}).then(() => {
    console.log('4');
}).catch(() => {
    console.log('5');
}).then(() => {
    console.log('6');
});
```
执行结果如下：
```javascript
1 
3 
5 
6
```
在这道题目中，我们需要知道，无论是then还是catch中，只要throw 抛出了错误，就会被catch捕获，如果没有throw出错误，就被继续执行后面的then。
<a name="9XlYz"></a>
### 31. 练习题
```javascript
setTimeout(function () {
  console.log(1);
}, 100);

new Promise(function (resolve) {
  console.log(2);
  resolve();
  console.log(3);
}).then(function () {
  console.log(4);
  new Promise((resove, reject) => {
    console.log(5);
    setTimeout(() =>  {
      console.log(6);
    }, 10);
  })
});
console.log(7);
console.log(8);
```
输出结果为：
```javascript
2
3
7
8
4
5
6
1
```
.then()之前都属于同步代码
